<?xml version='1.0' encoding='UTF-8'?>
<mujoco model="v1.1_Whole_u4.0_0304">
  <compiler angle="radian" meshdir="../meshes/" autolimits="true" discardvisual="false"/>
  <default>
    <joint damping="0.5" armature="0.01" frictionloss="0.1"/>
    <geom group="3" contype="1" conaffinity="1"/>
  </default>
  <asset>
    <mesh name="base_link" file="/home/user2/Instinct-mjlab/InstinctMJ/src/instinct_mj/assets/resources/v11/urdf/../meshes/base_link.STL"/>
    <mesh name="left_hip_pitch_link" file="/home/user2/Instinct-mjlab/InstinctMJ/src/instinct_mj/assets/resources/v11/urdf/../meshes/left_hip_pitch_link.STL"/>
    <mesh name="left_hip_roll_link" file="/home/user2/Instinct-mjlab/InstinctMJ/src/instinct_mj/assets/resources/v11/urdf/../meshes/left_hip_roll_link.STL"/>
    <mesh name="left_hip_yaw_link" file="/home/user2/Instinct-mjlab/InstinctMJ/src/instinct_mj/assets/resources/v11/urdf/../meshes/left_hip_yaw_link.STL"/>
    <mesh name="left_knee_link" file="/home/user2/Instinct-mjlab/InstinctMJ/src/instinct_mj/assets/resources/v11/urdf/../meshes/left_knee_link.STL"/>
    <mesh name="left_ankle_pitch_link" file="/home/user2/Instinct-mjlab/InstinctMJ/src/instinct_mj/assets/resources/v11/urdf/../meshes/left_ankle_pitch_link.STL"/>
    <mesh name="left_ankle_roll_link" file="/home/user2/Instinct-mjlab/InstinctMJ/src/instinct_mj/assets/resources/v11/urdf/../meshes/left_ankle_roll_link.STL"/>
    <mesh name="right_hip_pitch_link" file="/home/user2/Instinct-mjlab/InstinctMJ/src/instinct_mj/assets/resources/v11/urdf/../meshes/right_hip_pitch_link.STL"/>
    <mesh name="right_hip_roll_link" file="/home/user2/Instinct-mjlab/InstinctMJ/src/instinct_mj/assets/resources/v11/urdf/../meshes/right_hip_roll_link.STL"/>
    <mesh name="right_hip_yaw_link" file="/home/user2/Instinct-mjlab/InstinctMJ/src/instinct_mj/assets/resources/v11/urdf/../meshes/right_hip_yaw_link.STL"/>
    <mesh name="right_knee_link" file="/home/user2/Instinct-mjlab/InstinctMJ/src/instinct_mj/assets/resources/v11/urdf/../meshes/right_knee_link.STL"/>
    <mesh name="right_ankle_pitch_link" file="/home/user2/Instinct-mjlab/InstinctMJ/src/instinct_mj/assets/resources/v11/urdf/../meshes/right_ankle_pitch_link.STL"/>
    <mesh name="right_ankle_roll_link" file="/home/user2/Instinct-mjlab/InstinctMJ/src/instinct_mj/assets/resources/v11/urdf/../meshes/right_ankle_roll_link.STL"/>
    <mesh name="waist_yaw_link" file="/home/user2/Instinct-mjlab/InstinctMJ/src/instinct_mj/assets/resources/v11/urdf/../meshes/waist_yaw_link.STL"/>
    <mesh name="waist_roll_link" file="/home/user2/Instinct-mjlab/InstinctMJ/src/instinct_mj/assets/resources/v11/urdf/../meshes/waist_roll_link.STL"/>
    <mesh name="waist_pitch_link" file="/home/user2/Instinct-mjlab/InstinctMJ/src/instinct_mj/assets/resources/v11/urdf/../meshes/waist_pitch_link.STL"/>
    <mesh name="head_yaw_link" file="/home/user2/Instinct-mjlab/InstinctMJ/src/instinct_mj/assets/resources/v11/urdf/../meshes/head_yaw_link.STL"/>
    <mesh name="head_pitch_link" file="/home/user2/Instinct-mjlab/InstinctMJ/src/instinct_mj/assets/resources/v11/urdf/../meshes/head_pitch_link.STL"/>
    <mesh name="left_shoulder_pitch_link" file="/home/user2/Instinct-mjlab/InstinctMJ/src/instinct_mj/assets/resources/v11/urdf/../meshes/left_shoulder_pitch_link.STL"/>
    <mesh name="left_shoulder_roll_link" file="/home/user2/Instinct-mjlab/InstinctMJ/src/instinct_mj/assets/resources/v11/urdf/../meshes/left_shoulder_roll_link.STL"/>
    <mesh name="left_shoulder_yaw_link" file="/home/user2/Instinct-mjlab/InstinctMJ/src/instinct_mj/assets/resources/v11/urdf/../meshes/left_shoulder_yaw_link.STL"/>
    <mesh name="left_elbow_link" file="/home/user2/Instinct-mjlab/InstinctMJ/src/instinct_mj/assets/resources/v11/urdf/../meshes/left_elbow_link.STL"/>
    <mesh name="left_wrist_roll_link" file="/home/user2/Instinct-mjlab/InstinctMJ/src/instinct_mj/assets/resources/v11/urdf/../meshes/left_wrist_roll_link.STL"/>
    <mesh name="left_wrist_yaw_link" file="/home/user2/Instinct-mjlab/InstinctMJ/src/instinct_mj/assets/resources/v11/urdf/../meshes/left_wrist_yaw_link.STL"/>
    <mesh name="left_wrist_pitch_link" file="/home/user2/Instinct-mjlab/InstinctMJ/src/instinct_mj/assets/resources/v11/urdf/../meshes/left_wrist_pitch_link.STL"/>
    <mesh name="left_hand_link" file="/home/user2/Instinct-mjlab/InstinctMJ/src/instinct_mj/assets/resources/v11/urdf/../meshes/left_hand_link.STL"/>
    <mesh name="right_shoulder_pitch_link" file="/home/user2/Instinct-mjlab/InstinctMJ/src/instinct_mj/assets/resources/v11/urdf/../meshes/right_shoulder_pitch_link.STL"/>
    <mesh name="right_shoulder_roll_link" file="/home/user2/Instinct-mjlab/InstinctMJ/src/instinct_mj/assets/resources/v11/urdf/../meshes/right_shoulder_roll_link.STL"/>
    <mesh name="right_shoulder_yaw_link" file="/home/user2/Instinct-mjlab/InstinctMJ/src/instinct_mj/assets/resources/v11/urdf/../meshes/right_shoulder_yaw_link.STL"/>
    <mesh name="right_elbow_link" file="/home/user2/Instinct-mjlab/InstinctMJ/src/instinct_mj/assets/resources/v11/urdf/../meshes/right_elbow_link.STL"/>
    <mesh name="right_wrist_roll_link" file="/home/user2/Instinct-mjlab/InstinctMJ/src/instinct_mj/assets/resources/v11/urdf/../meshes/right_wrist_roll_link.STL"/>
    <mesh name="right_wrist_yaw_link" file="/home/user2/Instinct-mjlab/InstinctMJ/src/instinct_mj/assets/resources/v11/urdf/../meshes/right_wrist_yaw_link.STL"/>
    <mesh name="right_wrist_pitch_link" file="/home/user2/Instinct-mjlab/InstinctMJ/src/instinct_mj/assets/resources/v11/urdf/../meshes/right_wrist_pitch_link.STL"/>
    <mesh name="right_hand_link" file="/home/user2/Instinct-mjlab/InstinctMJ/src/instinct_mj/assets/resources/v11/urdf/../meshes/right_hand_link.STL"/>
  </asset>
  <worldbody>
    <body name="base_link">
      <inertial pos="-0.000155 2.8e-05 -0.049334" quat="0.505449 0.504747 -0.495115 0.494584" mass="5.77559" diaginertia="0.0309649 0.0287201 0.019774"/>
      <joint name="floating_base_joint" type="free" limited="false" actuatorfrclimited="false"/>
      <geom type="mesh" contype="0" conaffinity="0" group="1" density="0" rgba="0.2 0.2 0.2 1" mesh="base_link"/>
      <geom size="0.085" pos="0 0 -0.07" rgba="0.2 0.2 0.2 1"/>
      <site name="imu" size="0.01" pos="0 0 0"/>
      <body name="left_hip_pitch_link" pos="0 0.11619 -0.12455" quat="0.923879 -0.382684 0 0">
        <inertial pos="0.003459 0.021151 -0.028205" quat="0.490041 0.865639 0.102286 0.00818255" mass="2.31159" diaginertia="0.00539473 0.00466954 0.00409573"/>
        <joint name="left_hip_pitch_joint" pos="0 0 0" axis="0 1 0" range="-2.618 2.618" actuatorfrcrange="-150 150"/>
        <geom type="mesh" contype="0" conaffinity="0" group="1" density="0" rgba="0.75294 0.75294 0.75294 1" mesh="left_hip_pitch_link"/>
        <body name="left_hip_roll_link" pos="-0.001 0.03 -0.03" quat="0.923879 0.382684 0 0">
          <inertial pos="0.001718 2.7e-05 -0.084185" quat="0.302919 0.638937 0.638937 0.302919" mass="1.4811" diaginertia="0.004583 0.00342042 0.00297758"/>
          <joint name="left_hip_roll_joint" pos="0 0 0" axis="1 0 0" range="-0.7854 2.3563" actuatorfrcrange="-150 150"/>
          <geom type="mesh" contype="0" conaffinity="0" group="1" density="0" rgba="0.752941 0.752941 0.752941 1" mesh="left_hip_roll_link"/>
          <body name="left_hip_yaw_link" pos="0 0 -0.13">
            <inertial pos="-0.010515 -0.008686 -0.118125" quat="0.768791 -0.00106581 -0.0794954 0.634539" mass="2.40368" diaginertia="0.0105257 0.00964942 0.00307093"/>
            <joint name="left_hip_yaw_joint" pos="0 0 0" axis="0 0 1" range="-2.0944 2.0944" actuatorfrcrange="-90 90"/>
            <geom type="mesh" contype="0" conaffinity="0" group="1" density="0" rgba="0.752941 0.752941 0.752941 1" mesh="left_hip_yaw_link"/>
            <geom size="0.05 0.05" pos="0 0 0.05" type="capsule" rgba="0.752941 0.752941 0.752941 1"/>
            <body name="left_knee_link" pos="-0.015 0 -0.151">
              <inertial pos="0.004171 0.00067 -0.136787" quat="0.999909 0.00620724 0.0106815 -0.00541722" mass="1.79438" diaginertia="0.0104609 0.00988819 0.00191487"/>
              <joint name="left_knee_joint" pos="0 0 0" axis="0 1 0" range="-0.0873 2.0944" actuatorfrcrange="-150 150"/>
              <geom type="mesh" contype="0" conaffinity="0" group="1" density="0" rgba="0.752941 0.752941 0.752941 1" mesh="left_knee_link"/>
              <geom size="0.04 0.125" pos="0 0 -0.15" type="capsule" rgba="0.752941 0.752941 0.752941 1"/>
              <body name="left_ankle_pitch_link" pos="0.015 0.0005 -0.339">
                <inertial pos="-0.004439 8e-06 -0.007488" quat="0 0.83147 0 0.55557" mass="0.089167" diaginertia="2.22426e-05 1.9e-05 1.37574e-05"/>
                <joint name="left_ankle_pitch_joint" pos="0 0 0" axis="0 1 0" range="-0.9599 0.2618" actuatorfrcrange="-54 54"/>
                <geom type="mesh" contype="0" conaffinity="0" group="1" density="0" rgba="0.752941 0.752941 0.752941 1" mesh="left_ankle_pitch_link"/>
                <body name="left_ankle_roll_link" pos="0 0 -0.015">
                  <inertial pos="0.044355 0 -0.035553" quat="0 0.678893 0 0.734237" mass="0.881546" diaginertia="0.0045374 0.004457 0.000548603"/>
                  <joint name="left_ankle_roll_joint" pos="0 0 0" axis="1 0 0" range="-0.1745 0.1745" actuatorfrcrange="-54 54"/>
                  <geom type="mesh" contype="0" conaffinity="0" group="1" density="0" rgba="0.752941 0.752941 0.752941 1" mesh="left_ankle_roll_link"/>
                  <geom name="left_foot1_collision" size="0.012 0.08" pos="0.04 -0.03 -0.055" quat="0.710914 0 0.703279 0" type="capsule" priority="1" friction="0.6 0.005 0.0001" rgba="0.2 0.2 0.2 1"/>
                  <geom name="left_foot2_collision" size="0.012 0.1" pos="0.05 -0.02 -0.055" quat="0.710914 0 0.703279 0" type="capsule" priority="1" friction="0.6 0.005 0.0001" rgba="0.2 0.2 0.2 1"/>
                  <geom name="left_foot3_collision" size="0.012 0.11" pos="0.054 -0.01 -0.055" quat="0.710914 0 0.703279 0" type="capsule" priority="1" friction="0.6 0.005 0.0001" rgba="0.2 0.2 0.2 1"/>
                  <geom name="left_foot4_collision" size="0.012 0.11" pos="0.054 0 -0.055" quat="0.710914 0 0.703279 0" type="capsule" priority="1" friction="0.6 0.005 0.0001" rgba="0.2 0.2 0.2 1"/>
                  <geom name="left_foot5_collision" size="0.012 0.11" pos="0.054 0.01 -0.055" quat="0.710914 0 0.703279 0" type="capsule" priority="1" friction="0.6 0.005 0.0001" rgba="0.2 0.2 0.2 1"/>
                  <geom name="left_foot6_collision" size="0.012 0.1" pos="0.05 0.02 -0.055" quat="0.710914 0 0.703279 0" type="capsule" priority="1" friction="0.6 0.005 0.0001" rgba="0.2 0.2 0.2 1"/>
                  <geom name="left_foot7_collision" size="0.012 0.08" pos="0.04 0.03 -0.055" quat="0.710914 0 0.703279 0" type="capsule" priority="1" friction="0.6 0.005 0.0001" rgba="0.2 0.2 0.2 1"/>
                  <body name="LL_FOOT" pos="0.04 0 -0.037">
                    <inertial pos="0 0 0" mass="1e-09" diaginertia="0 0 0"/>
                  </body>
                  <site name="left_foot" pos="0.04 0 -0.037" size="0.01" rgba="1 0 0 1"/>
                </body>
              </body>
            </body>
          </body>
        </body>
      </body>
      <body name="right_hip_pitch_link" pos="0 -0.11619 -0.12455" quat="0.923879 0.382684 0 0">
        <inertial pos="0.00371 -0.021009 -0.028285" quat="0.871018 0.48043 -0.00149133 -0.102528" mass="2.32505" diaginertia="0.00543281 0.00471116 0.00414603"/>
        <joint name="right_hip_pitch_joint" pos="0 0 0" axis="0 1 0" range="-2.618 2.618" actuatorfrcrange="-150 150"/>
        <geom type="mesh" contype="0" conaffinity="0" group="1" density="0" rgba="0.752941 0.752941 0.752941 1" mesh="right_hip_pitch_link"/>
        <body name="right_hip_roll_link" pos="-0.001 -0.03 -0.03" quat="0.923879 -0.382684 0 0">
          <inertial pos="0.001726 -4e-06 -0.084185" quat="0.308158 0.639783 0.633678 0.306869" mass="1.4811" diaginertia="0.0045961 0.00341524 0.00296965"/>
          <joint name="right_hip_roll_joint" pos="0 0 0" axis="1 0 0" range="-2.3563 0.7854" actuatorfrcrange="-150 150"/>
          <geom type="mesh" contype="0" conaffinity="0" group="1" density="0" rgba="0.752941 0.752941 0.752941 1" mesh="right_hip_roll_link"/>
          <body name="right_hip_yaw_link" pos="0 0 -0.13">
            <inertial pos="-0.010501 0.008686 -0.118134" quat="0.634352 -0.0794556 -0.00101217 0.768949" mass="2.40369" diaginertia="0.0105269 0.00964795 0.00307314"/>
            <joint name="right_hip_yaw_joint" pos="0 0 0" axis="0 0 1" range="-2.0944 2.0944" actuatorfrcrange="-150 150"/>
            <geom type="mesh" contype="0" conaffinity="0" group="1" density="0" rgba="0.752941 0.752941 0.752941 1" mesh="right_hip_yaw_link"/>
            <geom size="0.05 0.05" pos="0 0 0.05" type="capsule" rgba="0.752941 0.752941 0.752941 1"/>
            <body name="right_knee_link" pos="-0.015 0 -0.151">
              <inertial pos="0.004171 -0.000665 -0.13679" quat="0.999908 -0.00626714 0.0106807 0.00545526" mass="1.79439" diaginertia="0.0104609 0.00989021 0.00191385"/>
              <joint name="right_knee_joint" pos="0 0 0" axis="0 1 0" range="-0.0873 2.0944" actuatorfrcrange="-150 150"/>
              <geom type="mesh" contype="0" conaffinity="0" group="1" density="0" rgba="0.752941 0.752941 0.752941 1" mesh="right_knee_link"/>
              <geom size="0.04 0.125" pos="0 0 -0.15" type="capsule" rgba="0.752941 0.752941 0.752941 1"/>
              <body name="right_ankle_pitch_link" pos="0.015 -0.0005 -0.339">
                <inertial pos="-0.004439 -8e-06 -0.007488" quat="0 0.83147 0 0.55557" mass="0.089167" diaginertia="2.22426e-05 1.9e-05 1.37574e-05"/>
                <joint name="right_ankle_pitch_joint" pos="0 0 0" axis="0 1 0" range="-0.9599 0.2618" actuatorfrcrange="-54 54"/>
                <geom type="mesh" contype="0" conaffinity="0" group="1" density="0" rgba="0.752941 0.752941 0.752941 1" mesh="right_ankle_pitch_link"/>
                <body name="right_ankle_roll_link" pos="0 0 -0.015">
                  <inertial pos="0.044597 0 -0.035822" quat="0 0.679635 0 0.733551" mass="0.874931" diaginertia="0.00452915 0.004442 0.000540846"/>
                  <joint name="right_ankle_roll_joint" pos="0 0 0" axis="1 0 0" range="-0.1745 0.1745" actuatorfrcrange="-54 54"/>
                  <geom type="mesh" contype="0" conaffinity="0" group="1" density="0" rgba="0.752941 0.752941 0.752941 1" mesh="right_ankle_roll_link"/>
                  <geom name="right_foot1_collision" size="0.012 0.08" pos="0.04 -0.03 -0.055" quat="0.710914 0 0.703279 0" type="capsule" priority="1" friction="0.6 0.005 0.0001" rgba="0.2 0.2 0.2 1"/>
                  <geom name="right_foot2_collision" size="0.012 0.1" pos="0.05 -0.02 -0.055" quat="0.710914 0 0.703279 0" type="capsule" priority="1" friction="0.6 0.005 0.0001" rgba="0.2 0.2 0.2 1"/>
                  <geom name="right_foot3_collision" size="0.012 0.11" pos="0.054 -0.01 -0.055" quat="0.710914 0 0.703279 0" type="capsule" priority="1" friction="0.6 0.005 0.0001" rgba="0.2 0.2 0.2 1"/>
                  <geom name="right_foot4_collision" size="0.012 0.11" pos="0.054 0 -0.055" quat="0.710914 0 0.703279 0" type="capsule" priority="1" friction="0.6 0.005 0.0001" rgba="0.2 0.2 0.2 1"/>
                  <geom name="right_foot5_collision" size="0.012 0.11" pos="0.054 0.01 -0.055" quat="0.710914 0 0.703279 0" type="capsule" priority="1" friction="0.6 0.005 0.0001" rgba="0.2 0.2 0.2 1"/>
                  <geom name="right_foot6_collision" size="0.012 0.1" pos="0.05 0.02 -0.055" quat="0.710914 0 0.703279 0" type="capsule" priority="1" friction="0.6 0.005 0.0001" rgba="0.2 0.2 0.2 1"/>
                  <geom name="right_foot7_collision" size="0.012 0.08" pos="0.04 0.03 -0.055" quat="0.710914 0 0.703279 0" type="capsule" priority="1" friction="0.6 0.005 0.0001" rgba="0.2 0.2 0.2 1"/>
                  <body name="LR_FOOT" pos="0.04 0 -0.037">
                    <inertial pos="0 0 0" mass="1e-09" diaginertia="0 0 0"/>
                  </body>
                  <site name="right_foot" pos="0.04 0 -0.037" size="0.01" rgba="1 0 0 1"/>
                </body>
              </body>
            </body>
          </body>
        </body>
      </body>
      <body name="waist_yaw_link">
        <inertial pos="-0.023393 1e-06 0.041219" quat="0 0.677318 0 0.73569" mass="0.2361" diaginertia="0.000486235 0.000381 0.000157765"/>
        <joint name="waist_yaw_joint" pos="0 0 0" axis="0 0 1" range="-1.5708 1.5708" actuatorfrcrange="-90 90"/>
        <geom type="mesh" contype="0" conaffinity="0" group="1" density="0" rgba="0.752941 0.752941 0.752941 1" mesh="waist_yaw_link"/>
        <body name="waist_roll_link" pos="0 0 0.0615">
          <inertial pos="0 0 -1.7e-05" quat="0 0.707107 0 0.707107" mass="0.044979" diaginertia="1.8e-05 1.3e-05 6e-06"/>
          <joint name="waist_roll_joint" pos="0 0 0" axis="1 0 0" range="-0.1745 0.1745" actuatorfrcrange="-90 90"/>
          <geom type="mesh" contype="0" conaffinity="0" group="1" density="0" rgba="0.752941 0.752941 0.752941 1" mesh="waist_roll_link"/>
          <body name="waist_pitch_link">
            <inertial pos="-0.006743 0.000129 0.239122" quat="0.99984 -0.00138923 -0.0177964 -0.000710682" mass="13.9753" diaginertia="0.216592 0.185444 0.0781879"/>
            <joint name="waist_pitch_joint" pos="0 0 0" axis="0 1 0" range="-0.3491 0.6981" actuatorfrcrange="-90 90"/>
            <geom type="mesh" contype="0" conaffinity="0" group="1" density="0" rgba="0.752941 0.752941 0.752941 1" mesh="waist_pitch_link"/>
            <geom size="0.08 0.0375" pos="0.005 0 0.35" quat="0.707105 0.707108 0 0" type="capsule" rgba="0.752941 0.752941 0.752941 1"/>
            <geom size="0.08 0.028" pos="0.005 0 0.2" quat="0.707105 0.707108 0 0" type="capsule" rgba="0.752941 0.752941 0.752941 1"/>
            <geom size="0.06 0.02" pos="0.005 0 0.06" quat="0.707105 0.707108 0 0" type="capsule" rgba="0.752941 0.752941 0.752941 1"/>
            <body name="head_yaw_link" pos="0 0 0.4375">
              <inertial pos="-0.001469 -0.001706 0.101301" quat="0.998467 -0.00882478 -0.00428167 0.0544812" mass="0.879937" diaginertia="0.00201828 0.00183516 0.00071856"/>
              <geom type="mesh" contype="0" conaffinity="0" group="1" density="0" rgba="0.752941 0.752941 0.752941 1" mesh="head_yaw_link"/>
              <geom size="0.07" pos="0 0 0.15" rgba="0.752941 0.752941 0.752941 1"/>
              <body name="head_pitch_link" pos="0 0 0.142">
                <inertial pos="0.024719 0.005163 0.054194" quat="0.275074 0.367039 0.169088 0.872368" mass="0.311827" diaginertia="0.000742282 0.000655865 0.000263853"/>
                <geom type="mesh" contype="0" conaffinity="0" group="1" density="0" rgba="0.752941 0.752941 0.752941 1" mesh="head_pitch_link"/>
              </body>
            </body>
            <body name="left_shoulder_pitch_link" pos="0 0.1446 0.3935">
              <inertial pos="0.005441 0.044691 -9e-06" quat="0.435162 0.557345 -0.435162 0.557345" mass="0.82606" diaginertia="0.000626 0.0006 0.000583"/>
              <joint name="left_shoulder_pitch_joint" pos="0 0 0" axis="0 1 0" range="-2.618 2.618" actuatorfrcrange="-80 80"/>
              <geom type="mesh" contype="0" conaffinity="0" group="1" density="0" rgba="0.752941 0.752941 0.752941 1" mesh="left_shoulder_pitch_link"/>
              <body name="left_shoulder_roll_link" pos="0 0.047 0">
                <inertial pos="0.004638 5.8e-05 -0.095341" quat="0.635553 -0.168427 -0.145122 0.739354" mass="0.919601" diaginertia="0.00159214 0.00158606 0.000733801"/>
                <joint name="left_shoulder_roll_joint" pos="0 0 0" axis="1 0 0" range="-0.0873 3.2289" actuatorfrcrange="-80 80"/>
                <geom type="mesh" contype="0" conaffinity="0" group="1" density="0" rgba="0.752941 0.752941 0.752941 1" mesh="left_shoulder_roll_link"/>
                <body name="left_shoulder_yaw_link" pos="-0.00072034 0 -0.1346">
                  <inertial pos="0.006217 0.007462 -0.090852" quat="0.819073 -0.0155607 0.0734932 0.56875" mass="1.02565" diaginertia="0.00155801 0.00150183 0.000799156"/>
                  <joint name="left_shoulder_yaw_joint" pos="0 0 0" axis="0 0 1" range="-2.618 2.618" actuatorfrcrange="-80 80"/>
                  <geom type="mesh" contype="0" conaffinity="0" group="1" density="0" rgba="0.752941 0.752941 0.752941 1" mesh="left_shoulder_yaw_link"/>
                  <geom size="0.035 0.075" type="capsule" rgba="0.752941 0.752941 0.752941 1"/>
                  <body name="left_elbow_link" pos="0.0075 0 -0.1019">
                    <inertial pos="0.08001 0.011386 -0.008325" quat="-0.0715389 0.633022 0.285541 0.715983" mass="0.57411" diaginertia="0.000881445 0.000795651 0.000284904"/>
                    <joint name="left_elbow_joint" pos="0 0 0" axis="0 1 0" range="-0.6981 3.3161" actuatorfrcrange="-80 80"/>
                    <geom type="mesh" contype="0" conaffinity="0" group="1" density="0" rgba="0.752941 0.752941 0.752941 1" mesh="left_elbow_link"/>
                    <geom size="0.035 0.075" pos="0.1 0 0" quat="0.707388 0 0.706825 0" type="capsule" rgba="0.752941 0.752941 0.752941 1"/>
                    <body name="left_wrist_roll_link" pos="0.1 0.0019 -0.009">
                      <inertial pos="0.084999 -4.2e-05 -0.005022" quat="0.534353 0.462261 0.462063 0.535986" mass="0.699715" diaginertia="0.001204 0.00112857 0.000441426"/>
                      <joint name="left_wrist_roll_joint" pos="0 0 0" axis="1 0 0" range="-2.618 2.618" actuatorfrcrange="-11.5 11.5"/>
                      <geom type="mesh" contype="0" conaffinity="0" group="1" density="0" rgba="0.752941 0.752941 0.752941 1" mesh="left_wrist_roll_link"/>
                      <body name="left_wrist_yaw_link" pos="0.1135 0 0">
                        <inertial pos="0.051009 0.006165 -0.002321" quat="0.211869 0.806792 0.349015 0.427068" mass="0.404102" diaginertia="0.000221574 0.000202653 0.000134773"/>
                        <joint name="left_wrist_yaw_joint" pos="0 0 0" axis="0 0 1" range="-1.6581 1.5708" actuatorfrcrange="-11.5 11.5"/>
                        <geom type="mesh" contype="0" conaffinity="0" group="1" density="0" rgba="0.752941 0.752941 0.752941 1" mesh="left_wrist_yaw_link"/>
                        <geom size="0.05 0.02" pos="0.09 0 0" quat="0.707388 0 0.706825 0" type="capsule" rgba="0.752941 0.752941 0.752941 1"/>
                        <body name="left_wrist_pitch_link" pos="0.054 0 0">
                          <inertial pos="0.03112 0.014397 0.000457" quat="0.706925 0.706925 -0.0160252 -0.0160252" mass="0.05282" diaginertia="0.000106 0.000106 0.000106"/>
                          <joint name="left_wrist_pitch_joint" pos="0 0 0" axis="0 1 0" range="-1.6581 1.4835" actuatorfrcrange="-11.5 11.5"/>
                          <geom type="mesh" contype="0" conaffinity="0" group="1" density="0" rgba="0.898039 0.917647 0.929412 1" mesh="left_wrist_pitch_link"/>
                          <body name="left_hand_link" pos="0.052 0 0.001">
                            <inertial pos="0.068357 -0.00813 0.010003" quat="0.686409 0.317601 0.557668 0.342022" mass="0.5" diaginertia="0.00154314 0.00114069 0.000539169"/>
                            <geom type="mesh" contype="0" conaffinity="0" group="1" density="0" rgba="1 1 1 1" mesh="left_hand_link"/>
                          </body>
                        </body>
                      </body>
                    </body>
                  </body>
                </body>
              </body>
            </body>
            <body name="right_shoulder_pitch_link" pos="0 -0.1446 0.3935">
              <inertial pos="0.00524 -0.044604 0" quat="0.540044 0.456457 -0.540044 0.456457" mass="0.823511" diaginertia="0.000621 0.000600676 0.000576324"/>
              <joint name="right_shoulder_pitch_joint" pos="0 0 0" axis="0 1 0" range="-2.618 2.618" actuatorfrcrange="-80 80"/>
              <geom type="mesh" contype="0" conaffinity="0" group="1" density="0" rgba="0.752941 0.752941 0.752941 1" mesh="right_shoulder_pitch_link"/>
              <body name="right_shoulder_roll_link" pos="0 -0.047 0">
                <inertial pos="0.004823 -6.6e-05 -0.094934" quat="0.689588 -0.156423 -0.156423 0.689588" mass="0.922881" diaginertia="0.00164 0.00163588 0.000734123"/>
                <joint name="right_shoulder_roll_joint" pos="0 0 0" axis="1 0 0" range="-3.2289 0.0873" actuatorfrcrange="-80 80"/>
                <geom type="mesh" contype="0" conaffinity="0" group="1" density="0" rgba="0.752941 0.752941 0.752941 1" mesh="right_shoulder_roll_link"/>
                <body name="right_shoulder_yaw_link" pos="-0.00072034 0 -0.1346">
                  <inertial pos="0.006215 -0.007444 -0.090877" quat="0.574371 0.0733484 -0.0145216 0.815173" mass="1.0263" diaginertia="0.00155813 0.00150352 0.000800349"/>
                  <joint name="right_shoulder_yaw_joint" pos="0 0 0" axis="0 0 1" range="-2.618 2.618" actuatorfrcrange="-80 80"/>
                  <geom type="mesh" contype="0" conaffinity="0" group="1" density="0" rgba="0.752941 0.752941 0.752941 1" mesh="right_shoulder_yaw_link"/>
                  <geom size="0.035 0.075" type="capsule" rgba="0.752941 0.752941 0.752941 1"/>
                  <body name="right_elbow_link" pos="0.0075 0 -0.1019">
                    <inertial pos="0.07929 -0.011745 -0.008251" quat="0.0594802 0.629275 -0.29337 0.717223" mass="0.579271" diaginertia="0.000926527 0.000837115 0.000286359"/>
                    <joint name="right_elbow_joint" pos="0 0 0" axis="0 1 0" range="-0.6981 3.3161" actuatorfrcrange="-80 80"/>
                    <geom type="mesh" contype="0" conaffinity="0" group="1" density="0" rgba="0.752941 0.752941 0.752941 1" mesh="right_elbow_link"/>
                    <geom size="0.035 0.075" pos="0.1 0 0" quat="0.707388 0 0.706825 0" type="capsule" rgba="0.752941 0.752941 0.752941 1"/>
                    <body name="right_wrist_roll_link" pos="0.1 -0.0019 -0.009">
                      <inertial pos="0.085003 4.9e-05 -0.00502" quat="0.536357 0.461633 0.461831 0.534722" mass="0.700041" diaginertia="0.001205 0.00112888 0.000442115"/>
                      <joint name="right_wrist_roll_joint" pos="0 0 0" axis="1 0 0" range="-2.618 2.618" actuatorfrcrange="-11.5 11.5"/>
                      <geom type="mesh" contype="0" conaffinity="0" group="1" density="0" rgba="0.752941 0.752941 0.752941 1" mesh="right_wrist_roll_link"/>
                      <body name="right_wrist_yaw_link" pos="0.1135 0 0">
                        <inertial pos="0.051094 -0.006168 -0.002269" quat="0.421711 0.367386 0.800912 0.213842" mass="0.404099" diaginertia="0.000219454 0.000201397 0.000135149"/>
                        <joint name="right_wrist_yaw_joint" pos="0 0 0" axis="0 0 1" range="-1.5708 1.6581" actuatorfrcrange="-11.5 11.5"/>
                        <geom pos="0 0 0" type="mesh" contype="0" conaffinity="0" group="1" density="0" rgba="0.752941 0.752941 0.752941 1" mesh="right_wrist_yaw_link"/>
                        <geom size="0.05 0.02" pos="0.09 0 0" quat="0.707388 0 0.706825 0" type="capsule" rgba="0.752941 0.752941 0.752941 1"/>
                        <body name="right_wrist_pitch_link" pos="0.054 0 0">
                          <inertial pos="0.03112 -0.014397 0.000457" quat="0.230106 0.668619 -0.230106 0.668619" mass="0.05282" diaginertia="3.8e-05 3.78078e-05 1.71922e-05"/>
                          <joint name="right_wrist_pitch_joint" pos="0 0 0" axis="0 1 0" range="-1.6581 1.4835" actuatorfrcrange="-11.5 11.5"/>
                          <geom type="mesh" contype="0" conaffinity="0" group="1" density="0" rgba="1 1 1 1" mesh="right_wrist_pitch_link"/>
                          <body name="right_hand_link" pos="0.054287 0 -0.01594">
                            <inertial pos="0.066084 0.008134 0.026947" quat="0.342022 0.557668 0.317601 0.686409" mass="0.5" diaginertia="0.00154314 0.00114069 0.000539169"/>
                            <geom type="mesh" contype="0" conaffinity="0" group="1" density="0" rgba="1 1 1 1" mesh="right_hand_link"/>
                          </body>
                        </body>
                      </body>
                    </body>
                  </body>
                </body>
              </body>
            </body>
          </body>
        </body>
      </body>
      <body name="imu_link" pos="-0.09835 0 -0.052"/>
    </body>
  </worldbody>
  <contact>
    <exclude body1="left_elbow_link" body2="left_wrist_pitch_link"/>
    <exclude body1="right_elbow_link" body2="right_wrist_pitch_link"/>
    <exclude body1="base_link" body2="left_hip_roll_link"/>
    <exclude body1="base_link" body2="right_hip_roll_link"/>
  </contact>
  <sensor>
    <framequat name="orientation" objtype="site" objname="imu"/>
    <framepos name="position" objtype="site" objname="imu"/>
    <gyro name="imu_ang_vel" site="imu"/>
    <velocimeter name="imu_lin_vel" site="imu"/>
    <accelerometer name="imu_lin_acc" site="imu"/>
    <subtreeangmom name="root_angmom" body="base_link"/>
  </sensor>
</mujoco>
